<?xml version="1.0" encoding="utf-8"?>
<!-- =================================================================================== -->
<!-- |    This document was not autogenerated by xacro from panda_arm_hand.urdf.xacro  | -->
<!-- |    EDITING THIS FILE BY HAND IS NOT RECOMMENDED but I edit it by hand           | -->
<!-- =================================================================================== -->
<robot name="rbotiq">
  <link name="root">
    <inertial>
      <mass value="0.01"/>
      <inertia ixx="1e-4" ixy="0.0" ixz="0.0" iyy="1e-4" iyz="0.0" izz="1e-4"/>
    </inertial>
  </link>
  <link name="root1">
    <inertial>
      <mass value="0.01"/>
      <inertia ixx="1e-4" ixy="0.0" ixz="0.0" iyy="1e-4" iyz="0.0" izz="1e-4"/>
    </inertial>
  </link>
  <link name="root2">
    <inertial>
      <mass value="0.01"/>
      <inertia ixx="1e-4" ixy="0.0" ixz="0.0" iyy="1e-4" iyz="0.0" izz="1e-4"/>
    </inertial>
  </link>
  <link name="root3">
    <inertial>
      <mass value="0.01"/>
      <inertia ixx="1e-4" ixy="0.0" ixz="0.0" iyy="1e-4" iyz="0.0" izz="1e-4"/>
    </inertial>
  </link>
  <link name="root4">
    <inertial>
      <mass value="0.01"/>
      <inertia ixx="1e-4" ixy="0.0" ixz="0.0" iyy="1e-4" iyz="0.0" izz="1e-4"/>
    </inertial>
  </link>
  <link name="root5">
    <inertial>
      <mass value="1"/>
      <inertia ixx="0.05" ixy="0.0" ixz="0.0" iyy="0.05" iyz="0.0" izz="0.05"/>
    </inertial>
  </link>
  <joint name="6dof_x_joint" type="prismatic">
    <parent link="root"/>
    <child link="root1"/>
    <axis xyz="1 0 0"/>
    <limit lower="-10" upper="10"/>
  </joint>
  <joint name="6dof_y_joint" type="prismatic">
    <parent link="root1"/>
    <child link="root2"/>
    <axis xyz="0 1 0"/>
    <limit lower="-10" upper="10"/>
  </joint>
  <joint name="6dof_z_joint" type="prismatic">
    <parent link="root2"/>
    <child link="root3"/>
    <axis xyz="0 0 1"/>
    <limit lower="-10" upper="10"/>
  </joint>
  <joint name="6dof_x_rotation_joint" type="continuous">
    <parent link="root3"/>
    <child link="root4"/>
    <axis xyz="1 0 0"/>
  </joint>
  <joint name="6dof_y_rotation_joint" type="continuous">
    <parent link="root4"/>
    <child link="root5"/>
    <axis xyz="0 1 0"/>
  </joint>
  <joint name="6dof_z_rotation_joint" type="continuous">
    <parent link="root5"/>
    <child link="robotiq_arg2f_base_link"/>
    <axis xyz="0 0 1"/>
  </joint>

  <!--  Begin Robotiq-140-->
  <link name="robotiq_arg2f_base_link">
    <inertial>
      <origin rpy="0 0 0" xyz="8.625E-08 -4.6583E-06 0.03145"/>
      <mass value="0.22652"/>
      <inertia ixx="0.00020005" ixy="-4.2442E-10" ixz="-2.9069E-10" iyy="0.00017832" iyz="-3.4402E-08"
               izz="0.00013478"/>
    </inertial>
    <visual>
      <origin rpy="0 0 0" xyz="0 0 0"/>
      <geometry>
        <mesh filename="robotiq_description/visual/robotiq_arg2f_base_link.dae"/>
      </geometry>
      <material name="">
        <color rgba="0.1 0.1 0.1 1"/>
      </material>
    </visual>
    <collision>
      <origin rpy="0 0 0" xyz="0 0 0"/>
      <geometry>
        <mesh filename="robotiq_description/collision/robotiq_arg2f_base_link.stl"/>
      </geometry>
    </collision>
  </link>
  <link name="grasp_convenient_link"/>
  <joint name="grasp_convenient_joint" type="fixed">
    <origin rpy="0 0 0" xyz="0 0 0.225"/>
    <parent link="robotiq_arg2f_base_link"/>
    <child link="grasp_convenient_link"/>
  </joint>
  <link name="left_outer_knuckle">
    <inertial>
      <origin rpy="0 0 0" xyz="-0.000200000000003065 0.0199435877845359 0.0292245259211331"/>
      <mass value="0.00853198276973456"/>
      <inertia ixx="2.89328108496468E-04" ixy="-1.57935047237397E-19" ixz="-1.93980378593255E-19"
               iyy="1.86719750325683E-04" iyz="-1.21858577871576E-04" izz="1.21905238907251E-04"/>
    </inertial>
    <visual>
      <origin rpy="0 0 0" xyz="0 0 0"/>
      <geometry>
        <mesh
            filename="robotiq_description/visual/robotiq_arg2f_140_outer_knuckle.dae"/>
      </geometry>
      <material name="">
        <color rgba="0.792156862745098 0.819607843137255 0.933333333333333 1"/>
      </material>
    </visual>
    <!--    <collision>-->
    <!--      <origin rpy="0 0 0" xyz="0 0 0"/>-->
    <!--      <geometry>-->
    <!--        <mesh-->
    <!--            filename="package://robotiq_2f_140_gripper_visualization/meshes/collision/robotiq_arg2f_140_outer_knuckle.stl"/>-->
    <!--      </geometry>-->
    <!--    </collision>-->
  </link>
  <link name="left_outer_finger">
    <inertial>
      <origin rpy="0 0 0" xyz="0.00030115855001899 0.0373907951953854 -0.0208027427000385"/>
      <mass value="0.022614240507152"/>
      <inertia ixx="1.52518312458174E-03" ixy="9.76583423954399E-10" ixz="-5.43838577022588E-10"
               iyy="6.17694243867776E-04" iyz="6.78636130740228E-04" izz="1.16494917907219E-03"/>
    </inertial>
    <visual>
      <origin rpy="0 0 0" xyz="0 0 0"/>
      <geometry>
        <mesh
            filename="robotiq_description/visual/robotiq_arg2f_140_outer_finger.dae"/>
      </geometry>
      <material name="">
        <color rgba="0.1 0.1 0.1 1"/>
      </material>
    </visual>
    <!--    <collision>-->
    <!--      <origin rpy="0 0 0" xyz="0 0 0"/>-->
    <!--      <geometry>-->
    <!--        <mesh-->
    <!--            filename="package://robotiq_2f_140_gripper_visualization/meshes/collision/robotiq_arg2f_140_outer_finger.stl"/>-->
    <!--      </geometry>-->
    <!--    </collision>-->
  </link>
  <link name="left_inner_finger">
    <inertial>
      <origin rpy="0 0 0" xyz="0.000299999999999317 0.0160078233491243 -0.0136945669206257"/>
      <mass value="0.0104003125914103"/>
      <inertia ixx="2.71909453810972E-04" ixy="1.35402465472579E-21" ixz="-7.1817349065269E-22"
               iyy="7.69100314106116E-05" iyz="6.74715432769696E-05" izz="2.30315190420171E-04"/>
    </inertial>
    <visual>
      <origin rpy="0 0 0" xyz="0 0 0"/>
      <geometry>
        <mesh
            filename="robotiq_description/visual/robotiq_arg2f_140_inner_finger.dae"/>
      </geometry>
      <material name="">
        <color rgba="0.1 0.1 0.1 1"/>
      </material>
    </visual>
  </link>
  <link name="left_inner_finger_pad">
    <visual>
      <origin rpy="0 0 0" xyz="0 0 0"/>
      <geometry>
        <box size="0.027 0.065 0.0075"/>
      </geometry>
      <material name="">
        <color rgba="0.9 0.9 0.9 1"/>
      </material>
    </visual>
    <collision>
      <origin rpy="0 0 0" xyz="0 0 0"/>
      <geometry>
        <box size="0.03 0.07 0.0075"/>
      </geometry>
      <material name="">
        <color rgba="0.9 0.0 0.0 1"/>
      </material>
    </collision>
  </link>
  <link name="left_inner_knuckle">
    <inertial>
      <origin rpy="0 0 0" xyz="0.000123011831763771 0.0507850843201817 0.00103968640075166"/>
      <mass value="0.0271177346495152"/>
      <inertia ixx="2.61910379223783E-03" ixy="-2.43616858946494E-05" ixz="-6.37789906117123E-09"
               iyy="2.8270243746167E-04" iyz="-5.37200748039765E-05" izz="2.83695868220296E-04"/>
    </inertial>
    <visual>
      <origin rpy="0 0 0" xyz="0 0 0"/>
      <geometry>
        <mesh
            filename="robotiq_description/visual/robotiq_arg2f_140_inner_knuckle.dae"/>
      </geometry>
      <material name="">
        <color rgba="0.1 0.1 0.1 1"/>
      </material>
    </visual>
  </link>
  <link name="right_outer_knuckle">
    <inertial>
      <origin rpy="0 0 0" xyz="-0.000200000000003065 0.0199435877845359 0.0292245259211331"/>
      <mass value="0.00853198276973456"/>
      <inertia ixx="2.89328108496468E-06" ixy="-1.57935047237397E-19" ixz="-1.93980378593255E-19"
               iyy="1.86719750325683E-06" iyz="-1.21858577871576E-06" izz="1.21905238907251E-06"/>
    </inertial>
    <visual>
      <origin rpy="0 0 0" xyz="0 0 0"/>
      <geometry>
        <mesh
            filename="robotiq_description/visual/robotiq_arg2f_140_outer_knuckle.dae"/>
      </geometry>
      <material name="">
        <color rgba="0.792156862745098 0.819607843137255 0.933333333333333 1"/>
      </material>
    </visual>
  </link>
  <link name="right_outer_finger">
    <inertial>
      <origin rpy="0 0 0" xyz="0.00030115855001899 0.0373907951953854 -0.0208027427000385"/>
      <mass value="0.022614240507152"/>
      <inertia ixx="1.52518312458174E-03" ixy="9.76583423954399E-10" ixz="-5.43838577022588E-10"
               iyy="6.17694243867776E-03" iyz="6.78636130740228E-04" izz="1.16494917907219E-03"/>
    </inertial>
    <visual>
      <origin rpy="0 0 0" xyz="0 0 0"/>
      <geometry>
        <mesh
            filename="robotiq_description/visual/robotiq_arg2f_140_outer_finger.dae"/>
      </geometry>
      <material name="">
        <color rgba="0.1 0.1 0.1 1"/>
      </material>
    </visual>
  </link>
  <link name="right_inner_finger">
    <inertial>
      <origin rpy="0 0 0" xyz="0.000299999999999317 0.0160078233491243 -0.0136945669206257"/>
      <mass value="0.0104003125914103"/>
      <inertia ixx="2.71909453810972E-03" ixy="1.35402465472579E-21" ixz="-7.1817349065269E-22"
               iyy="7.69100314106116E-04" iyz="6.74715432769696E-04" izz="2.30315190420171E-03"/>
    </inertial>
    <visual>
      <origin rpy="0 0 0" xyz="0 0 0"/>
      <geometry>
        <mesh
            filename="robotiq_description/visual/robotiq_arg2f_140_inner_finger.dae"/>
      </geometry>
      <material name="">
        <color rgba="0.1 0.1 0.1 1"/>
      </material>
    </visual>
  </link>
  <link name="right_inner_finger_pad">
    <visual>
      <origin rpy="0 0 0" xyz="0 0 0"/>
      <geometry>
        <box size="0.027 0.065 0.0075"/>
      </geometry>
      <material name="">
        <color rgba="0.9 0.9 0.9 1"/>
      </material>
    </visual>
    <collision>
      <origin rpy="0 0 0" xyz="0 0 0"/>
      <geometry>
        <box size="0.03 0.07 0.0075"/>
      </geometry>
      <material name="">
        <color rgba="0.9 0.0 0.0 1"/>
      </material>
    </collision>
  </link>
  <link name="right_inner_knuckle">
    <inertial>
      <origin rpy="0 0 0" xyz="0.000123011831763771 0.0507850843201817 0.00103968640075166"/>
      <mass value="0.0271177346495152"/>
      <inertia ixx="2.61910379223783E-02" ixy="-2.43616858946494E-04" ixz="-6.37789906117123E-06"
               iyy="2.8270243746167E-03" iyz="-5.37200748039765E-04" izz="2.83695868220296E-02"/>
    </inertial>
    <visual>
      <origin rpy="0 0 0" xyz="0 0 0"/>
      <geometry>
        <mesh
            filename="robotiq_description/visual/robotiq_arg2f_140_inner_knuckle.dae"/>
      </geometry>
      <material name="">
        <color rgba="0.1 0.1 0.1 1"/>
      </material>
    </visual>
  </link>

  <joint name="robotiq_2f_140_left_driver_joint" type="prismatic">
    <origin rpy="1.57079 0 0" xyz="0 -0.068 0.177"/>
    <parent link="robotiq_arg2f_base_link"/>
    <child link="left_inner_finger_pad"/>
    <axis xyz="0 0.35112344 -0.93632918"/>
    <limit effort="1000" lower="0" upper="0.06835" velocity="2.0"/>
  </joint>
  <joint name="robotiq_2f_140_right_driver_joint" type="prismatic">
    <origin rpy="1.57079 0 -3.14" xyz="0 0.068 0.177"/>
    <parent link="robotiq_arg2f_base_link"/>
    <child link="right_inner_finger_pad"/>
    <axis xyz="0 0.35112344 -0.93632918"/>
    <limit effort="1000" lower="0" upper="0.06835" velocity="2.0"/>
  </joint>

  <joint name="robotiq_2f_140_left_driver_mimic_joint" type="fixed">
    <origin rpy="2.29579632679 0 0" xyz="0 -0.030601 0.054905"/>
    <parent link="robotiq_arg2f_base_link"/>
    <child link="left_outer_knuckle"/>
    <axis xyz="-1 0 0"/>
<!--    <limit effort="1000" lower="0" upper="0.725" velocity="2.0"/>-->
<!--    <mimic joint="robotiq_2f_140_left_driver_joint" multiplier="-1" offset="0"/>-->
  </joint>
  <joint name="robotiq_2f_140_left_coupler_joint" type="fixed">
    <origin rpy="0 0 0" xyz="0 0.01821998610742 0.0260018192872234"/>
    <parent link="left_outer_knuckle"/>
    <child link="left_outer_finger"/>
    <axis xyz="1 0 0"/>
  </joint>
  <joint name="robotiq_2f_140_left_spring_link_joint" type="fixed">
    <origin rpy="2.29579632679 0 0.0" xyz="0 -0.0127 0.06142"/>
    <parent link="robotiq_arg2f_base_link"/>
    <child link="left_inner_knuckle"/>
    <axis xyz="-1 0 0"/>
<!--    <limit effort="1000" lower="0" upper="0.8757" velocity="2.0"/>-->
<!--    <mimic joint="robotiq_2f_140_left_driver_joint" multiplier="-1" offset="0"/>-->
  </joint>
  <joint name="robotiq_2f_140_left_pad_joint" type="fixed">
    <origin rpy="0 0 0" xyz="0 -0.0457554015893473 0.0272203446692936"/>
    <child link="left_inner_finger"/>
    <parent link="left_inner_finger_pad"/>
    <axis xyz="0 0 1"/>
  </joint>

  <joint name="robotiq_2f_140_right_driver_mimic_joint" type="fixed">
    <origin rpy="2.29579632679 0 3.14159265359" xyz="0 0.030601 0.054905"/>
    <parent link="robotiq_arg2f_base_link"/>
    <child link="right_outer_knuckle"/>
    <axis xyz="-1 0 0"/>
<!--    <limit effort="1000" lower="0.0" upper="0.725" velocity="2.0"/>-->
<!--    <mimic joint="robotiq_2f_140_left_driver_joint" multiplier="-1" offset="0"/>-->
  </joint>
  <joint name="robotiq_2f_140_right_coupler_joint" type="fixed">
    <origin rpy="0 0 0" xyz="0 0.01821998610742 0.0260018192872234"/>
    <parent link="right_outer_knuckle"/>
    <child link="right_outer_finger"/>
    <axis xyz="1 0 0"/>
  </joint>
  <joint name="robotiq_2f_140_right_spring_link_joint" type="fixed">
    <origin rpy="2.29579632679 0 -3.14159265359" xyz="0 0.0127 0.06142"/>
    <parent link="robotiq_arg2f_base_link"/>
    <child link="right_inner_knuckle"/>
    <axis xyz="-1 0 0"/>
<!--    <limit effort="1000" lower="0" upper="0.8757" velocity="2.0"/>-->
<!--    <mimic joint="robotiq_2f_140_left_driver_joint" multiplier="-1" offset="0"/>-->
  </joint>
  <joint name="robotiq_2f_140_right_pad_joint" type="fixed">
    <origin rpy="0 0 0" xyz="0 -0.0457554015893473 0.0272203446692936"/>
    <child link="right_inner_finger"/>
    <parent link="right_inner_finger_pad"/>
    <axis xyz="0 0 1"/>
  </joint>
</robot>

